Workbook

Sheet Dashboard
A1: 📊 DASHBOARD — VISÃO GERAL DO DEPARTAMENTO
A2: Resumo consolidado de todos os consórcios, sistemas e automações.
B4: Receita Mensal (mensalidades) | C4: CAPEX Total (sistemas + automações) | D4: Total Mensal c/ CAPEX diluído | E4: Economia Anual Automações | F4: Nº Consórcios Ativos
B5: =SUM('Extrato Consorcios'!E5:E20) -> 45220 | C5: =SUM('Extrato Consorcios'!G5:G20)+SUM('Extrato Consorcios'!I5:I20) -> 1022216 | D5: =SUM('Extrato Consorcios'!K5:K20) -> 103259.44 | E5: =SUM('Extrato Consorcios'!N5:N20) -> 1026098.1 | F5: =COUNTA(Consorcios!B5:B24) -> 13
A7: 💳 RESUMO POR CONSÓRCIO
A8: # | B8: Consórcio | C8: Porte | D8: Mensalidade (R$) | E8: CAPEX/mês total (R$) | F8: Total Mensal (R$)
A9: 1 | B9: ='Extrato Consorcios'!B5 -> Consórcio BGGK | C9: ='Extrato Consorcios'!D5 -> Pequeno | D9: ='Extrato Consorcios'!E5 -> 1904 | E9: ='Extrato Consorcios'!H5+'Extrato Consorcios'!J5 -> 2221.3333 | F9: ='Extrato Consorcios'!K5 -> 4125.3333
A10: 2 | B10: ='Extrato Consorcios'!B6 -> COHAB SANTOS | C10: ='Extrato Consorcios'!D6 -> Micro | D10: ='Extrato Consorcios'!E6 -> 952 | E10: ='Extrato Consorcios'!H6+'Extrato Consorcios'!J6 -> 3391.5 | F10: ='Extrato Consorcios'!K6 -> 4343.5
A11: 3 | B11: ='Extrato Consorcios'!B7 -> Consórcio BJMM | C11: ='Extrato Consorcios'!D7 -> Medio | D11: ='Extrato Consorcios'!E7 -> 2856 | E11: ='Extrato Consorcios'!H7+'Extrato Consorcios'!J7 -> 8885.3333 | F11: ='Extrato Consorcios'!K7 -> 11741.333
A12: 4 | B12: ='Extrato Consorcios'!B8 -> ELETROBRAS | C12: ='Extrato Consorcios'!D8 -> Micro | D12: ='Extrato Consorcios'!E8 -> 238 | E12: ='Extrato Consorcios'!H8+'Extrato Consorcios'!J8 -> 3173.3333 | F12: ='Extrato Consorcios'!K8 -> 3411.3333
A13: 5 | B13: ='Extrato Consorcios'!B9 -> Consórcio HABITA GERENCIAL | C13: ='Extrato Consorcios'!D9 -> Medio | D13: ='Extrato Consorcios'!E9 -> 3808 | E13: ='Extrato Consorcios'!H9+'Extrato Consorcios'!J9 -> 12058.667 | F13: ='Extrato Consorcios'!K9 -> 15866.667
A14: 6 | B14: ='Extrato Consorcios'!B10 -> Consórcio HABITA SOCIAL | C14: ='Extrato Consorcios'!D10 -> Grande | D14: ='Extrato Consorcios'!E10 -> 952 | E14: ='Extrato Consorcios'!H10+'Extrato Consorcios'!J10 -> 2916 | F14: ='Extrato Consorcios'!K10 -> 3868
A15: 7 | B15: ='Extrato Consorcios'!B11 -> Macaé Petrobrás | C15: ='Extrato Consorcios'!D11 -> Medio | D15: ='Extrato Consorcios'!E11 -> 4760 | E15: ='Extrato Consorcios'!H11+'Extrato Consorcios'!J11 -> 5751.6667 | F15: ='Extrato Consorcios'!K11 -> 10511.667
A16: 8 | B16: ='Extrato Consorcios'!B12 -> Consórcio REURBSP | C16: ='Extrato Consorcios'!D12 -> Grande | D16: ='Extrato Consorcios'!E12 -> 7616 | E16: ='Extrato Consorcios'!H12+'Extrato Consorcios'!J12 -> 0 | F16: ='Extrato Consorcios'!K12 -> 7616
A17: 9 | C17: ='Extrato Consorcios'!D20 | D17: ='Extrato Consorcios'!E20 | E17: ='Extrato Consorcios'!H20+'Extrato Consorcios'!J20 -> 0 | F17: ='Extrato Consorcios'!K20

Sheet Config
A1: ⚙️ CONFIGURAÇÃO DE FAIXAS DE PORTE — Definição pela Diretoria de Operações
A2: Todos os cálculos da planilha se atualizam a partir deste cadastro. Células em AZUL são editáveis pela diretoria.
A4: 💰 FAIXAS — VALOR DO CONTRATO (R$) | G4: 👥 FAIXAS — Nº DE BENEFICIÁRIOS | K4: 💳 COBRANÇA MENSAL POR PORTE
A5: # | B5: Faixa / Nome | C5: Valor Mínimo (R$) | D5: Valor Máximo (R$) | E5: Peso (%) | G5: Faixa / Nome | H5: Mín. | I5: Máx. | J5: Peso (%) | K5: Horas/mês destinadas | L5: Mensalidade (R$) = h × R$238
A6: 1 | B6: Micro | C6: 0 | D6: 5000000 | E6: 0.15 | G6: Micro | H6: 0 | I6: 10 | J6: 0.15 | K6: 4 | L6: =K6*$E$12 -> 952
A7: 2 | B7: Pequeno | C7: 5000001 | D7: 10000000 | E7: 0.35 | G7: Pequeno | H7: 11 | I7: 25 | J7: 0.35 | K7: 8 | L7: =K7*$E$12 -> 1904
A8: 3 | B8: Medio | C8: 10000001 | D8: 20000000 | E8: 0.65 | G8: Medio | H8: 26 | I8: 60 | J8: 0.65 | K8: 16 | L8: =K8*$E$12 -> 3808
A9: 4 | B9: Grande | C9: 20000001 | D9: 999999999 | E9: 1 | G9: Grande | H9: 61 | I9: 999999 | J9: 1 | K9: 32 | L9: =K9*$E$12 -> 7616
A11: 🏗️ REGRAS DE CAPEX — IMPLANTAÇÃO
B12: Custo/hora desenvolvimento | E12: 238
B13: Forma padrão de cobrança CAPEX | E13: À vista ou diluído (definir por consórcio)
B14: Prazo máximo de diluição | E14: 24 meses
A16: 🎨 LEGENDA DE CORES
A17: Azul — Input editável
A18: Verde — Resultado / ROI positivo
A19: Laranja — Custo / investimento / CAPEX
A20: Roxo — Cobrança por consórcio
A21: Cinza — Calculado automaticamente

Sheet Consorcios
A1: 🏢 CADASTRO DE CONSÓRCIOS — Índice de Porte e Cobrança
A2: Cada consórcio recebe índice de porte e mensalidade calculados automaticamente pelas faixas configuradas.
B3: IDENTIFICAÇÃO | D3: 💰 DADOS DO CONTRATO | H3: 📊 ÍNDICE DE PORTE | K3: 💳 COBRANÇA
A4: # | B4: Nome do Consórcio | C4: Empresa Gestora | D4: Valor Contrato (R$) | E4: Faixa Valor | F4: Nº Beneficiários | G4: Faixa Benef. | H4: Peso Valor | I4: Peso Benef. | J4: Índice de Porte | K4: Horas/mês | L4: Mensalidade (R$)
A5: 1 | B5: Consórcio BGGK | C5: Bonin Construtora | D5: 4157093.6 | E5: =IF(D5="","",IF(D5<=Config!$D$6,Config!$B$6,IF(D5<=Config!$D$7,Config!$B$7,IF(D5<=Config!$D$8,Config!$B$8,IF(D5>=Config!$C$9,Config!$B$9,"—"))))) -> Micro | F5: 13 | G5: =IF(F5="","",IF(F5<=Config!$I$6,Config!$G$6,IF(F5<=Config!$I$7,Config!$G$7,IF(F5<=Config!$I$8,Config!$G$8,IF(F5>=Config!$H$9,Config!$G$9,"—"))))) -> Pequeno | H5: =IF(D5="","",IF(D5<=Config!$D$6,Config!$E$6,IF(D5<=Config!$D$7,Config!$E$7,IF(D5<=Config!$D$8,Config!$E$8,IF(D5>=Config!$C$9,Config!$E$9,"—"))))) -> 0.15 | I5: =IF(F5="","",IF(F5<=Config!$I$6,Config!$J$6,IF(F5<=Config!$I$7,Config!$J$7,IF(F5<=Config!$I$8,Config!$J$8,IF(F5>=Config!$H$9,Config!$J$9,"—"))))) -> 0.35 | J5: =IF(D5="","",IFERROR((H5+I5)/2,"—")) -> 0.25 | K5: =IF(J5="","",IF(J5<0.25,Config!$K$6,IF(J5<0.5,Config!$K$7,IF(J5<0.75,Config!$K$8,IF(J5>=0.75,Config!$K$9,0))))) -> 8 | L5: =IFERROR(K5*Config!$E$12,"") -> 1904
A6: 2 | B6: COHAB SANTOS | C6: COHAB | D6: 1211000 | E6: =IF(D6="","",IF(D6<=Config!$D$6,Config!$B$6,IF(D6<=Config!$D$7,Config!$B$7,IF(D6<=Config!$D$8,Config!$B$8,IF(D6>=Config!$C$9,Config!$B$9,"—"))))) -> Micro | F6: 4 | G6: =IF(F6="","",IF(F6<=Config!$I$6,Config!$G$6,IF(F6<=Config!$I$7,Config!$G$7,IF(F6<=Config!$I$8,Config!$G$8,IF(F6>=Config!$H$9,Config!$G$9,"—"))))) -> Micro | H6: =IF(D6="","",IF(D6<=Config!$D$6,Config!$E$6,IF(D6<=Config!$D$7,Config!$E$7,IF(D6<=Config!$D$8,Config!$E$8,IF(D6>=Config!$C$9,Config!$E$9,"—"))))) -> 0.15 | I6: =IF(F6="","",IF(F6<=Config!$I$6,Config!$J$6,IF(F6<=Config!$I$7,Config!$J$7,IF(F6<=Config!$I$8,Config!$J$8,IF(F6>=Config!$H$9,Config!$J$9,"—"))))) -> 0.15 | J6: =IF(D6="","",IFERROR((H6+I6)/2,"—")) -> 0.15 | K6: =IF(J6="","",IF(J6<0.25,Config!$K$6,IF(J6<0.5,Config!$K$7,IF(J6<0.75,Config!$K$8,IF(J6>=0.75,Config!$K$9,0))))) -> 4 | L6: =IFERROR(K6*Config!$E$12,"") -> 952
A7: 3 | B7: Consórcio BJMM | C7: Bonin+Parceiros | D7: 1.0599804e+08 | E7: =IF(D7="","",IF(D7<=Config!$D$6,Config!$B$6,IF(D7<=Config!$D$7,Config!$B$7,IF(D7<=Config!$D$8,Config!$B$8,IF(D7>=Config!$C$9,Config!$B$9,"—"))))) -> Grande | F7: 19 | G7: =IF(F7="","",IF(F7<=Config!$I$6,Config!$G$6,IF(F7<=Config!$I$7,Config!$G$7,IF(F7<=Config!$I$8,Config!$G$8,IF(F7>=Config!$H$9,Config!$G$9,"—"))))) -> Pequeno | H7: =IF(D7="","",IF(D7<=Config!$D$6,Config!$E$6,IF(D7<=Config!$D$7,Config!$E$7,IF(D7<=Config!$D$8,Config!$E$8,IF(D7>=Config!$C$9,Config!$E$9,"—"))))) -> 1 | I7: =IF(F7="","",IF(F7<=Config!$I$6,Config!$J$6,IF(F7<=Config!$I$7,Config!$J$7,IF(F7<=Config!$I$8,Config!$J$8,IF(F7>=Config!$H$9,Config!$J$9,"—"))))) -> 0.35 | J7: =IF(D7="","",IFERROR((H7+I7)/2,"—")) -> 0.675 | K7: 12 | L7: =IFERROR(K7*Config!$E$12,"") -> 2856
A8: 4 | B8: ELETROBRAS | C8: Eletrobras | D8: 2096384.1 | E8: =IF(D8="","",IF(D8<=Config!$D$6,Config!$B$6,IF(D8<=Config!$D$7,Config!$B$7,IF(D8<=Config!$D$8,Config!$B$8,IF(D8>=Config!$C$9,Config!$B$9,"—"))))) -> Micro | F8: 2 | G8: =IF(F8="","",IF(F8<=Config!$I$6,Config!$G$6,IF(F8<=Config!$I$7,Config!$G$7,IF(F8<=Config!$I$8,Config!$G$8,IF(F8>=Config!$H$9,Config!$G$9,"—"))))) -> Micro | H8: =IF(D8="","",IF(D8<=Config!$D$6,Config!$E$6,IF(D8<=Config!$D$7,Config!$E$7,IF(D8<=Config!$D$8,Config!$E$8,IF(D8>=Config!$C$9,Config!$E$9,"—"))))) -> 0.15 | I8: =IF(F8="","",IF(F8<=Config!$I$6,Config!$J$6,IF(F8<=Config!$I$7,Config!$J$7,IF(F8<=Config!$I$8,Config!$J$8,IF(F8>=Config!$H$9,Config!$J$9,"—"))))) -> 0.15 | J8: =IF(D8="","",IFERROR((H8+I8)/2,"—")) -> 0.15 | K8: 1 | L8: =IFERROR(K8*Config!$E$12,"") -> 238
A9: 5 | B9: Consórcio HABITA GERENCIAL | C9: Bonin | D9: 1.3055103e+08 | E9: =IF(D9="","",IF(D9<=Config!$D$6,Config!$B$6,IF(D9<=Config!$D$7,Config!$B$7,IF(D9<=Config!$D$8,Config!$B$8,IF(D9>=Config!$C$9,Config!$B$9,"—"))))) -> Grande | F9: 11 | G9: =IF(F9="","",IF(F9<=Config!$I$6,Config!$G$6,IF(F9<=Config!$I$7,Config!$G$7,IF(F9<=Config!$I$8,Config!$G$8,IF(F9>=Config!$H$9,Config!$G$9,"—"))))) -> Pequeno | H9: =IF(D9="","",IF(D9<=Config!$D$6,Config!$E$6,IF(D9<=Config!$D$7,Config!$E$7,IF(D9<=Config!$D$8,Config!$E$8,IF(D9>=Config!$C$9,Config!$E$9,"—"))))) -> 1 | I9: =IF(F9="","",IF(F9<=Config!$I$6,Config!$J$6,IF(F9<=Config!$I$7,Config!$J$7,IF(F9<=Config!$I$8,Config!$J$8,IF(F9>=Config!$H$9,Config!$J$9,"—"))))) -> 0.35 | J9: =IF(D9="","",IFERROR((H9+I9)/2,"—")) -> 0.675 | K9: 16 | L9: =IFERROR(K9*Config!$E$12,"") -> 3808
A10: 6 | B10: Consórcio HABITA SOCIAL | C10: Bonin | D10: 1.5395014e+08 | E10: =IF(D10="","",IF(D10<=Config!$D$6,Config!$B$6,IF(D10<=Config!$D$7,Config!$B$7,IF(D10<=Config!$D$8,Config!$B$8,IF(D10>=Config!$C$9,Config!$B$9,"—"))))) -> Grande | F10: 120 | G10: =IF(F10="","",IF(F10<=Config!$I$6,Config!$G$6,IF(F10<=Config!$I$7,Config!$G$7,IF(F10<=Config!$I$8,Config!$G$8,IF(F10>=Config!$H$9,Config!$G$9,"—"))))) -> Grande | H10: =IF(D10="","",IF(D10<=Config!$D$6,Config!$E$6,IF(D10<=Config!$D$7,Config!$E$7,IF(D10<=Config!$D$8,Config!$E$8,IF(D10>=Config!$C$9,Config!$E$9,"—"))))) -> 1 | I10: =IF(F10="","",IF(F10<=Config!$I$6,Config!$J$6,IF(F10<=Config!$I$7,Config!$J$7,IF(F10<=Config!$I$8,Config!$J$8,IF(F10>=Config!$H$9,Config!$J$9,"—"))))) -> 1 | J10: =IF(D10="","",IFERROR((H10+I10)/2,"—")) -> 1 | K10: 4 | L10: =IFERROR(K10*Config!$E$12,"") -> 952
A11: 7 | B11: Macaé Petrobrás | C11: Bonin Engenharia | D11: 13299032 | E11: =IF(D11="","",IF(D11<=Config!$D$6,Config!$B$6,IF(D11<=Config!$D$7,Config!$B$7,IF(D11<=Config!$D$8,Config!$B$8,IF(D11>=Config!$C$9,Config!$B$9,"—"))))) -> Medio | F11: 15 | G11: =IF(F11="","",IF(F11<=Config!$I$6,Config!$G$6,IF(F11<=Config!$I$7,Config!$G$7,IF(F11<=Config!$I$8,Config!$G$8,IF(F11>=Config!$H$9,Config!$G$9,"—"))))) -> Pequeno | H11: =IF(D11="","",IF(D11<=Config!$D$6,Config!$E$6,IF(D11<=Config!$D$7,Config!$E$7,IF(D11<=Config!$D$8,Config!$E$8,IF(D11>=Config!$C$9,Config!$E$9,"—"))))) -> 0.65 | I11: =IF(F11="","",IF(F11<=Config!$I$6,Config!$J$6,IF(F11<=Config!$I$7,Config!$J$7,IF(F11<=Config!$I$8,Config!$J$8,IF(F11>=Config!$H$9,Config!$J$9,"—"))))) -> 0.35 | J11: =IF(D11="","",IFERROR((H11+I11)/2,"—")) -> 0.5 | K11: 20 | L11: =IFERROR(K11*Config!$E$12,"") -> 4760
A12: 8 | B12: Consórcio REURBSP | C12: Bonin Engenharia | D12: 40442028 | E12: =IF(D12="","",IF(D12<=Config!$D$6,Config!$B$6,IF(D12<=Config!$D$7,Config!$B$7,IF(D12<=Config!$D$8,Config!$B$8,IF(D12>=Config!$C$9,Config!$B$9,"—"))))) -> Grande | F12: 80 | G12: =IF(F12="","",IF(F12<=Config!$I$6,Config!$G$6,IF(F12<=Config!$I$7,Config!$G$7,IF(F12<=Config!$I$8,Config!$G$8,IF(F12>=Config!$H$9,Config!$G$9,"—"))))) -> Grande | H12: =IF(D12="","",IF(D12<=Config!$D$6,Config!$E$6,IF(D12<=Config!$D$7,Config!$E$7,IF(D12<=Config!$D$8,Config!$E$8,IF(D12>=Config!$C$9,Config!$E$9,"—"))))) -> 1 | I12: =IF(F12="","",IF(F12<=Config!$I$6,Config!$J$6,IF(F12<=Config!$I$7,Config!$J$7,IF(F12<=Config!$I$8,Config!$J$8,IF(F12>=Config!$H$9,Config!$J$9,"—"))))) -> 1 | J12: =IF(D12="","",IFERROR((H12+I12)/2,"—")) -> 1 | K12: =IF(J12="","",IF(J12<0.25,Config!$K$6,IF(J12<0.5,Config!$K$7,IF(J12<0.75,Config!$K$8,IF(J12>=0.75,Config!$K$9,0))))) -> 32 | L12: =IFERROR(K12*Config!$E$12,"") -> 7616
A13: 9 | B13: Consórcio URBHIS | C13: Bonin Engenharia | D13: 1.2983029e+08 | E13: =IF(D13="","",IF(D13<=Config!$D$6,Config!$B$6,IF(D13<=Config!$D$7,Config!$B$7,IF(D13<=Config!$D$8,Config!$B$8,IF(D13>=Config!$C$9,Config!$B$9,"—"))))) -> Grande | F13: 100 | G13: =IF(F13="","",IF(F13<=Config!$I$6,Config!$G$6,IF(F13<=Config!$I$7,Config!$G$7,IF(F13<=Config!$I$8,Config!$G$8,IF(F13>=Config!$H$9,Config!$G$9,"—"))))) -> Grande | H13: =IF(D13="","",IF(D13<=Config!$D$6,Config!$E$6,IF(D13<=Config!$D$7,Config!$E$7,IF(D13<=Config!$D$8,Config!$E$8,IF(D13>=Config!$C$9,Config!$E$9,"—"))))) -> 1 | I13: =IF(F13="","",IF(F13<=Config!$I$6,Config!$J$6,IF(F13<=Config!$I$7,Config!$J$7,IF(F13<=Config!$I$8,Config!$J$8,IF(F13>=Config!$H$9,Config!$J$9,"—"))))) -> 1 | J13: =IF(D13="","",IFERROR((H13+I13)/2,"—")) -> 1 | K13: 40 | L13: =IFERROR(K13*Config!$E$12,"") -> 9520
A14: 10 | B14: Vinci Notificações | C14: Bonin Engenharia | D14: 3095472 | E14: =IF(D14="","",IF(D14<=Config!$D$6,Config!$B$6,IF(D14<=Config!$D$7,Config!$B$7,IF(D14<=Config!$D$8,Config!$B$8,IF(D14>=Config!$C$9,Config!$B$9,"—"))))) -> Micro | F14: 5 | G14: =IF(F14="","",IF(F14<=Config!$I$6,Config!$G$6,IF(F14<=Config!$I$7,Config!$G$7,IF(F14<=Config!$I$8,Config!$G$8,IF(F14>=Config!$H$9,Config!$G$9,"—"))))) -> Micro | H14: =IF(D14="","",IF(D14<=Config!$D$6,Config!$E$6,IF(D14<=Config!$D$7,Config!$E$7,IF(D14<=Config!$D$8,Config!$E$8,IF(D14>=Config!$C$9,Config!$E$9,"—"))))) -> 0.15 | I14: =IF(F14="","",IF(F14<=Config!$I$6,Config!$J$6,IF(F14<=Config!$I$7,Config!$J$7,IF(F14<=Config!$I$8,Config!$J$8,IF(F14>=Config!$H$9,Config!$J$9,"—"))))) -> 0.15 | J14: =IF(D14="","",IFERROR((H14+I14)/2,"—")) -> 0.15 | K14: 5 | L14: =IFERROR(K14*Config!$E$12,"") -> 1190
A15: 11 | B15: COSAN | C15: Bonin Engenharia | D15: 893714.94 | E15: =IF(D15="","",IF(D15<=Config!$D$6,Config!$B$6,IF(D15<=Config!$D$7,Config!$B$7,IF(D15<=Config!$D$8,Config!$B$8,IF(D15>=Config!$C$9,Config!$B$9,"—"))))) -> Micro | F15: 10 | G15: =IF(F15="","",IF(F15<=Config!$I$6,Config!$G$6,IF(F15<=Config!$I$7,Config!$G$7,IF(F15<=Config!$I$8,Config!$G$8,IF(F15>=Config!$H$9,Config!$G$9,"—"))))) -> Micro | H15: =IF(D15="","",IF(D15<=Config!$D$6,Config!$E$6,IF(D15<=Config!$D$7,Config!$E$7,IF(D15<=Config!$D$8,Config!$E$8,IF(D15>=Config!$C$9,Config!$E$9,"—"))))) -> 0.15 | I15: =IF(F15="","",IF(F15<=Config!$I$6,Config!$J$6,IF(F15<=Config!$I$7,Config!$J$7,IF(F15<=Config!$I$8,Config!$J$8,IF(F15>=Config!$H$9,Config!$J$9,"—"))))) -> 0.15 | J15: =IF(D15="","",IFERROR((H15+I15)/2,"—")) -> 0.15 | K15: =IF(J15="","",IF(J15<0.25,Config!$K$6,IF(J15<0.5,Config!$K$7,IF(J15<0.75,Config!$K$8,IF(J15>=0.75,Config!$K$9,0))))) -> 4 | L15: =IFERROR(K15*Config!$E$12,"") -> 952
A16: 12 | B16: Consórcio BGPI | C16: Bonin Engenharia | D16: 15259208 | E16: =IF(D16="","",IF(D16<=Config!$D$6,Config!$B$6,IF(D16<=Config!$D$7,Config!$B$7,IF(D16<=Config!$D$8,Config!$B$8,IF(D16>=Config!$C$9,Config!$B$9,"—"))))) -> Medio | F16: 12 | G16: =IF(F16="","",IF(F16<=Config!$I$6,Config!$G$6,IF(F16<=Config!$I$7,Config!$G$7,IF(F16<=Config!$I$8,Config!$G$8,IF(F16>=Config!$H$9,Config!$G$9,"—"))))) -> Pequeno | H16: =IF(D16="","",IF(D16<=Config!$D$6,Config!$E$6,IF(D16<=Config!$D$7,Config!$E$7,IF(D16<=Config!$D$8,Config!$E$8,IF(D16>=Config!$C$9,Config!$E$9,"—"))))) -> 0.65 | I16: =IF(F16="","",IF(F16<=Config!$I$6,Config!$J$6,IF(F16<=Config!$I$7,Config!$J$7,IF(F16<=Config!$I$8,Config!$J$8,IF(F16>=Config!$H$9,Config!$J$9,"—"))))) -> 0.35 | J16: =IF(D16="","",IFERROR((H16+I16)/2,"—")) -> 0.5 | K16: 12 | L16: =IFERROR(K16*Config!$E$12,"") -> 2856
A17: 13 | B17: Consórcio Habita REURBSP | C17: Bonin Engenharia | D17: 1.1748079e+08 | E17: =IF(D17="","",IF(D17<=Config!$D$6,Config!$B$6,IF(D17<=Config!$D$7,Config!$B$7,IF(D17<=Config!$D$8,Config!$B$8,IF(D17>=Config!$C$9,Config!$B$9,"—"))))) -> Grande | F17: 80 | G17: =IF(F17="","",IF(F17<=Config!$I$6,Config!$G$6,IF(F17<=Config!$I$7,Config!$G$7,IF(F17<=Config!$I$8,Config!$G$8,IF(F17>=Config!$H$9,Config!$G$9,"—"))))) -> Grande | H17: =IF(D17="","",IF(D17<=Config!$D$6,Config!$E$6,IF(D17<=Config!$D$7,Config!$E$7,IF(D17<=Config!$D$8,Config!$E$8,IF(D17>=Config!$C$9,Config!$E$9,"—"))))) -> 1 | I17: =IF(F17="","",IF(F17<=Config!$I$6,Config!$J$6,IF(F17<=Config!$I$7,Config!$J$7,IF(F17<=Config!$I$8,Config!$J$8,IF(F17>=Config!$H$9,Config!$J$9,"—"))))) -> 1 | J17: =IF(D17="","",IFERROR((H17+I17)/2,"—")) -> 1 | K17: =IF(J17="","",IF(J17<0.25,Config!$K$6,IF(J17<0.5,Config!$K$7,IF(J17<0.75,Config!$K$8,IF(J17>=0.75,Config!$K$9,0))))) -> 32 | L17: =IFERROR(K17*Config!$E$12,"") -> 7616
A18: 14 | E18: =IF(D18="","",IF(D18<=Config!$D$6,Config!$B$6,IF(D18<=Config!$D$7,Config!$B$7,IF(D18<=Config!$D$8,Config!$B$8,IF(D18>=Config!$C$9,Config!$B$9,"—"))))) | G18: =IF(F18="","",IF(F18<=Config!$I$6,Config!$G$6,IF(F18<=Config!$I$7,Config!$G$7,IF(F18<=Config!$I$8,Config!$G$8,IF(F18>=Config!$H$9,Config!$G$9,"—"))))) | H18: =IF(D18="","",IF(D18<=Config!$D$6,Config!$E$6,IF(D18<=Config!$D$7,Config!$E$7,IF(D18<=Config!$D$8,Config!$E$8,IF(D18>=Config!$C$9,Config!$E$9,"—"))))) | I18: =IF(F18="","",IF(F18<=Config!$I$6,Config!$J$6,IF(F18<=Config!$I$7,Config!$J$7,IF(F18<=Config!$I$8,Config!$J$8,IF(F18>=Config!$H$9,Config!$J$9,"—"))))) | J18: =IF(D18="","",IFERROR((H18+I18)/2,"—")) | K18: =IF(J18="","",IF(J18<0.25,Config!$K$6,IF(J18<0.5,Config!$K$7,IF(J18<0.75,Config!$K$8,IF(J18>=0.75,Config!$K$9,0))))) | L18: =IFERROR(K18*Config!$E$12,"")
A19: 15 | E19: =IF(D19="","",IF(D19<=Config!$D$6,Config!$B$6,IF(D19<=Config!$D$7,Config!$B$7,IF(D19<=Config!$D$8,Config!$B$8,IF(D19>=Config!$C$9,Config!$B$9,"—"))))) | G19: =IF(F19="","",IF(F19<=Config!$I$6,Config!$G$6,IF(F19<=Config!$I$7,Config!$G$7,IF(F19<=Config!$I$8,Config!$G$8,IF(F19>=Config!$H$9,Config!$G$9,"—"))))) | H19: =IF(D19="","",IF(D19<=Config!$D$6,Config!$E$6,IF(D19<=Config!$D$7,Config!$E$7,IF(D19<=Config!$D$8,Config!$E$8,IF(D19>=Config!$C$9,Config!$E$9,"—"))))) | I19: =IF(F19="","",IF(F19<=Config!$I$6,Config!$J$6,IF(F19<=Config!$I$7,Config!$J$7,IF(F19<=Config!$I$8,Config!$J$8,IF(F19>=Config!$H$9,Config!$J$9,"—"))))) | J19: =IF(D19="","",IFERROR((H19+I19)/2,"—")) | K19: =IF(J19="","",IF(J19<0.25,Config!$K$6,IF(J19<0.5,Config!$K$7,IF(J19<0.75,Config!$K$8,IF(J19>=0.75,Config!$K$9,0))))) | L19: =IFERROR(K19*Config!$E$12,"")
A20: 16 | E20: =IF(D20="","",IF(D20<=Config!$D$6,Config!$B$6,IF(D20<=Config!$D$7,Config!$B$7,IF(D20<=Config!$D$8,Config!$B$8,IF(D20>=Config!$C$9,Config!$B$9,"—"))))) | G20: =IF(F20="","",IF(F20<=Config!$I$6,Config!$G$6,IF(F20<=Config!$I$7,Config!$G$7,IF(F20<=Config!$I$8,Config!$G$8,IF(F20>=Config!$H$9,Config!$G$9,"—"))))) | H20: =IF(D20="","",IF(D20<=Config!$D$6,Config!$E$6,IF(D20<=Config!$D$7,Config!$E$7,IF(D20<=Config!$D$8,Config!$E$8,IF(D20>=Config!$C$9,Config!$E$9,"—"))))) | I20: =IF(F20="","",IF(F20<=Config!$I$6,Config!$J$6,IF(F20<=Config!$I$7,Config!$J$7,IF(F20<=Config!$I$8,Config!$J$8,IF(F20>=Config!$H$9,Config!$J$9,"—"))))) | J20: =IF(D20="","",IFERROR((H20+I20)/2,"—")) | K20: =IF(J20="","",IF(J20<0.25,Config!$K$6,IF(J20<0.5,Config!$K$7,IF(J20<0.75,Config!$K$8,IF(J20>=0.75,Config!$K$9,0))))) | L20: =IFERROR(K20*Config!$E$12,"")
A21: 17 | E21: =IF(D21="","",IF(D21<=Config!$D$6,Config!$B$6,IF(D21<=Config!$D$7,Config!$B$7,IF(D21<=Config!$D$8,Config!$B$8,IF(D21>=Config!$C$9,Config!$B$9,"—"))))) | G21: =IF(F21="","",IF(F21<=Config!$I$6,Config!$G$6,IF(F21<=Config!$I$7,Config!$G$7,IF(F21<=Config!$I$8,Config!$G$8,IF(F21>=Config!$H$9,Config!$G$9,"—"))))) | H21: =IF(D21="","",IF(D21<=Config!$D$6,Config!$E$6,IF(D21<=Config!$D$7,Config!$E$7,IF(D21<=Config!$D$8,Config!$E$8,IF(D21>=Config!$C$9,Config!$E$9,"—"))))) | I21: =IF(F21="","",IF(F21<=Config!$I$6,Config!$J$6,IF(F21<=Config!$I$7,Config!$J$7,IF(F21<=Config!$I$8,Config!$J$8,IF(F21>=Config!$H$9,Config!$J$9,"—"))))) | J21: =IF(D21="","",IFERROR((H21+I21)/2,"—")) | K21: =IF(J21="","",IF(J21<0.25,Config!$K$6,IF(J21<0.5,Config!$K$7,IF(J21<0.75,Config!$K$8,IF(J21>=0.75,Config!$K$9,0))))) | L21: =IFERROR(K21*Config!$E$12,"")
A22: 18 | E22: =IF(D22="","",IF(D22<=Config!$D$6,Config!$B$6,IF(D22<=Config!$D$7,Config!$B$7,IF(D22<=Config!$D$8,Config!$B$8,IF(D22>=Config!$C$9,Config!$B$9,"—"))))) | G22: =IF(F22="","",IF(F22<=Config!$I$6,Config!$G$6,IF(F22<=Config!$I$7,Config!$G$7,IF(F22<=Config!$I$8,Config!$G$8,IF(F22>=Config!$H$9,Config!$G$9,"—"))))) | H22: =IF(D22="","",IF(D22<=Config!$D$6,Config!$E$6,IF(D22<=Config!$D$7,Config!$E$7,IF(D22<=Config!$D$8,Config!$E$8,IF(D22>=Config!$C$9,Config!$E$9,"—"))))) | I22: =IF(F22="","",IF(F22<=Config!$I$6,Config!$J$6,IF(F22<=Config!$I$7,Config!$J$7,IF(F22<=Config!$I$8,Config!$J$8,IF(F22>=Config!$H$9,Config!$J$9,"—"))))) | J22: =IF(D22="","",IFERROR((H22+I22)/2,"—")) | K22: =IF(J22="","",IF(J22<0.25,Config!$K$6,IF(J22<0.5,Config!$K$7,IF(J22<0.75,Config!$K$8,IF(J22>=0.75,Config!$K$9,0))))) | L22: =IFERROR(K22*Config!$E$12,"")
A23: 19 | E23: =IF(D23="","",IF(D23<=Config!$D$6,Config!$B$6,IF(D23<=Config!$D$7,Config!$B$7,IF(D23<=Config!$D$8,Config!$B$8,IF(D23>=Config!$C$9,Config!$B$9,"—"))))) | G23: =IF(F23="","",IF(F23<=Config!$I$6,Config!$G$6,IF(F23<=Config!$I$7,Config!$G$7,IF(F23<=Config!$I$8,Config!$G$8,IF(F23>=Config!$H$9,Config!$G$9,"—"))))) | H23: =IF(D23="","",IF(D23<=Config!$D$6,Config!$E$6,IF(D23<=Config!$D$7,Config!$E$7,IF(D23<=Config!$D$8,Config!$E$8,IF(D23>=Config!$C$9,Config!$E$9,"—"))))) | I23: =IF(F23="","",IF(F23<=Config!$I$6,Config!$J$6,IF(F23<=Config!$I$7,Config!$J$7,IF(F23<=Config!$I$8,Config!$J$8,IF(F23>=Config!$H$9,Config!$J$9,"—"))))) | J23: =IF(D23="","",IFERROR((H23+I23)/2,"—")) | K23: =IF(J23="","",IF(J23<0.25,Config!$K$6,IF(J23<0.5,Config!$K$7,IF(J23<0.75,Config!$K$8,IF(J23>=0.75,Config!$K$9,0))))) | L23: =IFERROR(K23*Config!$E$12,"")
A24: 20 | E24: =IF(D24="","",IF(D24<=Config!$D$6,Config!$B$6,IF(D24<=Config!$D$7,Config!$B$7,IF(D24<=Config!$D$8,Config!$B$8,IF(D24>=Config!$C$9,Config!$B$9,"—"))))) | G24: =IF(F24="","",IF(F24<=Config!$I$6,Config!$G$6,IF(F24<=Config!$I$7,Config!$G$7,IF(F24<=Config!$I$8,Config!$G$8,IF(F24>=Config!$H$9,Config!$G$9,"—"))))) | H24: =IF(D24="","",IF(D24<=Config!$D$6,Config!$E$6,IF(D24<=Config!$D$7,Config!$E$7,IF(D24<=Config!$D$8,Config!$E$8,IF(D24>=Config!$C$9,Config!$E$9,"—"))))) | I24: =IF(F24="","",IF(F24<=Config!$I$6,Config!$J$6,IF(F24<=Config!$I$7,Config!$J$7,IF(F24<=Config!$I$8,Config!$J$8,IF(F24>=Config!$H$9,Config!$J$9,"—"))))) | J24: =IF(D24="","",IFERROR((H24+I24)/2,"—")) | K24: =IF(J24="","",IF(J24<0.25,Config!$K$6,IF(J24<0.5,Config!$K$7,IF(J24<0.75,Config!$K$8,IF(J24>=0.75,Config!$K$9,0))))) | L24: =IFERROR(K24*Config!$E$12,"")

Sheet Sistemas ERP
A1: 🖥️ SISTEMAS / ERP — Cadastro por Instância e Consórcio
A2: Cada linha = uma instância de sistema em um consórcio. Registre para controle e cálculo de CAPEX.
A3: IDENTIFICAÇÃO | D3: 🏗️ CAPEX — IMPLANTAÇÃO | G3: 📅 DILUIÇÃO DO CAPEX | I3: 💰 CUSTO MENSAL CAPEX
A4: # | B4: Sistema / Nome | C4: Consórcio | D4: Horas Dev | E4: Custo/h (R$) | F4: CAPEX Total (R$) | G4: Forma | H4: Prazo (meses) | I4: Parcela CAPEX/mês (R$) | J4: CAPEX Acumulado (R$)
A5: 1 | B5: POWER APP - ARROLAMENTO | C5: Consórcio URBHIS | D5: 4800 | E5: 238 | F5: =(D5/60)*E5 -> 19040 | G5: Diluido | H5: 24 | I5: =IF(OR(F5="",H5=""),"",IF(G5="À vista",F5,IFERROR(F5/H5,""))) -> 793.33333 | J5: =IF(F5="","",F5) -> 19040
A6: 2 | B6: POWER APP - ATEND. PLANTÃO | C6: Consórcio URBHIS | D6: 2400 | E6: 238 | F6: =(D6/60)*E6 -> 9520 | G6: Diluido | H6: 24 | I6: =IF(OR(F6="",H6=""),"",IF(G6="À vista",F6,IFERROR(F6/H6,""))) -> 396.66667 | J6: =IF(F6="","",F6) -> 9520
A7: 3 | B7: POWER APP - SIGD GERENCIAMENTO | C7: Consórcio URBHIS | D7: 9600 | E7: 238 | F7: =(D7/60)*E7 -> 38080 | G7: Diluido | H7: 24 | I7: =IF(OR(F7="",H7=""),"",IF(G7="À vista",F7,IFERROR(F7/H7,""))) -> 1586.6667 | J7: =IF(F7="","",F7) -> 38080
A8: 4 | B8: POWER APP - SIGD P14 | C8: Consórcio URBHIS | D8: =60*8*5 -> 2400 | E8: 238 | F8: =(D8/60)*E8 -> 9520 | G8: Diluido | H8: 24 | I8: =IF(OR(F8="",H8=""),"",IF(G8="À vista",F8,IFERROR(F8/H8,""))) -> 396.66667 | J8: =IF(F8="","",F8) -> 9520
A9: 5 | B9: POWER APP - BONIN - VINCI GERENCIAMENTO DE NOTIFICAÇÕES | C9: Vinci Notificações | D9: =8*60*10 -> 4800 | E9: 238 | F9: =(D9/60)*E9 -> 19040 | G9: Diluido | H9: 12 | I9: =IF(OR(F9="",H9=""),"",IF(G9="À vista",F9,IFERROR(F9/H9,""))) -> 1586.6667 | J9: =IF(F9="","",F9) -> 19040
A10: 6 | B10: POWER APP - BONIN - VINCI NOTIFICAÇÕES | C10: Vinci Notificações | D10: =60*8*6 -> 2880 | E10: 238 | F10: =(D10/60)*E10 -> 11424 | G10: Diluido | H10: 12 | I10: =IF(OR(F10="",H10=""),"",IF(G10="À vista",F10,IFERROR(F10/H10,""))) -> 952 | J10: =IF(F10="","",F10) -> 11424
A11: 7 | B11: POWER APP - CONSÓRCIO CABIÚNAS - GERENCIAMENTO | C11: Macaé Petrobrás | D11: =60*8*20 -> 9600 | E11: 238 | F11: =(D11/60)*E11 -> 38080 | G11: Diluido | H11: 12 | I11: =IF(OR(F11="",H11=""),"",IF(G11="À vista",F11,IFERROR(F11/H11,""))) -> 3173.3333 | J11: =IF(F11="","",F11) -> 38080
A12: 8 | B12: POWER APP - HABITA - LANÇAMENTO DE KM | C12: Consórcio HABITA SOCIAL | D12: =60*8*10 -> 4800 | E12: 93.75 | F12: =(D12/60)*E12 -> 7500 | G12: Diluido | H12: 12 | I12: =IF(OR(F12="",H12=""),"",IF(G12="À vista",F12,IFERROR(F12/H12,""))) -> 625 | J12: =IF(F12="","",F12) -> 7500
A13: 9 | B13: POWER APP - HABITA - CONTROLE DE FROTAS | C13: Consórcio HABITA SOCIAL | D13: =60*8*10 -> 4800 | E13: 93.75 | F13: =(D13/60)*E13 -> 7500 | G13: Diluido | H13: 12 | I13: =IF(OR(F13="",H13=""),"",IF(G13="À vista",F13,IFERROR(F13/H13,""))) -> 625 | J13: =IF(F13="","",F13) -> 7500
A14: 10 | B14: POWER APP - HABITA SOCIAL - CONTROLE DE PLANEJAMENTO | C14: Consórcio HABITA SOCIAL | D14: =60*8*5 -> 2400 | E14: 238 | F14: =(D14/60)*E14 -> 9520 | G14: Diluido | H14: 12 | I14: =IF(OR(F14="",H14=""),"",IF(G14="À vista",F14,IFERROR(F14/H14,""))) -> 793.33333 | J14: =IF(F14="","",F14) -> 9520
A15: 11 | B15: WEB - System-cohab-santos | C15: COHAB SANTOS | D15: =8*60*6 -> 2880 | E15: 238 | F15: =(D15/60)*E15 -> 11424 | G15: Diluido | H15: 12 | I15: =IF(OR(F15="",H15=""),"",IF(G15="À vista",F15,IFERROR(F15/H15,""))) -> 952 | J15: =IF(F15="","",F15) -> 11424
A16: 12 | B16: APP ANDROID - ARROLAMENTO | C16: COHAB SANTOS | D16: =8*60*15 -> 7200 | E16: 238 | F16: =(D16/60)*E16 -> 28560 | G16: Diluido | H16: 12 | I16: =IF(OR(F16="",H16=""),"",IF(G16="À vista",F16,IFERROR(F16/H16,""))) -> 2380 | J16: =IF(F16="","",F16) -> 28560
A17: 13 | B17: SIGD - CONSÓRCIO BGGK | C17: Consórcio BGGK | D17: =60*8*5 -> 2400 | E17: 238 | F17: =(D17/60)*E17 -> 9520 | G17: Diluido | H17: 12 | I17: =IF(OR(F17="",H17=""),"",IF(G17="À vista",F17,IFERROR(F17/H17,""))) -> 793.33333 | J17: =IF(F17="","",F17) -> 9520
A18: 14 | B18: BGGK - SISTEMA DE CAMPO | C18: Consórcio BGGK | D18: =60*8*8 -> 3840 | E18: 238 | F18: =(D18/60)*E18 -> 15232 | G18: Diluido | H18: 12 | I18: =IF(OR(F18="",H18=""),"",IF(G18="À vista",F18,IFERROR(F18/H18,""))) -> 1269.3333 | J18: =IF(F18="","",F18) -> 15232
A19: 16 | B19: HABITA GERENCIAL - CONTROLE DE RECIBOS | C19: Consórcio HABITA GERENCIAL | D19: =60*8*13 -> 6240 | E19: 238 | F19: =(D19/60)*E19 -> 24752 | G19: Diluido | H19: 12 | I19: =IF(OR(F19="",H19=""),"",IF(G19="À vista",F19,IFERROR(F19/H19,""))) -> 2062.6667 | J19: =IF(F19="","",F19) -> 24752
A20: 18 | B20: SIGD - HABITA GERENCIAL | C20: Consórcio HABITA GERENCIAL | D20: =60*8*5 -> 2400 | E20: 238 | F20: =(D20/60)*E20 -> 9520 | G20: Diluido | H20: 12 | I20: =IF(OR(F20="",H20=""),"",IF(G20="À vista",F20,IFERROR(F20/H20,""))) -> 793.33333 | J20: =IF(F20="","",F20) -> 9520
A21: 19 | B21: HABITA GERENCIAL - SISTEMA DE CAMPO | C21: Consórcio HABITA GERENCIAL | D21: =60*8*8 -> 3840 | E21: 238 | F21: =(D21/60)*E21 -> 15232 | G21: Diluido | H21: 12 | I21: =IF(OR(F21="",H21=""),"",IF(G21="À vista",F21,IFERROR(F21/H21,""))) -> 1269.3333 | J21: =IF(F21="","",F21) -> 15232
A22: 20 | B22: GESTÃO DE DOCUMENTOS (GED) | C22: ELETROBRAS | D22: =60*8*20 -> 9600 | E22: 238 | F22: =(D22/60)*E22 -> 38080 | G22: Diluido | H22: 12 | I22: =IF(OR(F22="",H22=""),"",IF(G22="À vista",F22,IFERROR(F22/H22,""))) -> 3173.3333 | J22: =IF(F22="","",F22) -> 38080
A23: 21 | B23: COSAN - SIGD | C23: COSAN | D23: =60*8*5 -> 2400 | E23: 238 | F23: =(D23/60)*E23 -> 9520 | G23: Diluido | H23: 12 | I23: =IF(OR(F23="",H23=""),"",IF(G23="À vista",F23,IFERROR(F23/H23,""))) -> 793.33333 | J23: =IF(F23="","",F23) -> 9520
A24: 22 | B24: COSAN - SISTEMA DE CAMPO | C24: COSAN | D24: =60*8*8 -> 3840 | E24: 238 | F24: =(D24/60)*E24 -> 15232 | G24: Diluido | H24: 12 | I24: =IF(OR(F24="",H24=""),"",IF(G24="À vista",F24,IFERROR(F24/H24,""))) -> 1269.3333 | J24: =IF(F24="","",F24) -> 15232
A25: 23 | B25: COSAN - CONTROLE DE ARQUIVOS | C25: COSAN | D25: =60*8*14 -> 6720 | E25: 238 | F25: =(D25/60)*E25 -> 26656 | G25: Diluido | H25: 12 | I25: =IF(OR(F25="",H25=""),"",IF(G25="À vista",F25,IFERROR(F25/H25,""))) -> 2221.3333 | J25: =IF(F25="","",F25) -> 26656
A26: 24 | B26: BJMM - GERENCIAMENTO | C26: Consórcio BJMM | D26: =60*8*15 -> 7200 | E26: 238 | F26: =(D26/60)*E26 -> 28560 | G26: Diluido | H26: 12 | I26: =IF(OR(F26="",H26=""),"",IF(G26="À vista",F26,IFERROR(F26/H26,""))) -> 2380 | J26: =IF(F26="","",F26) -> 28560
A27: 25 | B27: BJMM - SISTEMA DE VISTORIA | C27: Consórcio BJMM | D27: =60*8*7 -> 3360 | E27: 238 | F27: =(D27/60)*E27 -> 13328 | G27: Diluido | H27: 12 | I27: =IF(OR(F27="",H27=""),"",IF(G27="À vista",F27,IFERROR(F27/H27,""))) -> 1110.6667 | J27: =IF(F27="","",F27) -> 13328
A28: 26 | B28: GED | C28: Consórcio BJMM | D28: =60*8*20 -> 9600 | E28: 238 | F28: =(D28/60)*E28 -> 38080 | G28: Diluido | H28: 12 | I28: =IF(OR(F28="",H28=""),"",IF(G28="À vista",F28,IFERROR(F28/H28,""))) -> 3173.3333 | J28: =IF(F28="","",F28) -> 38080
A29: 27 | B29: BGPI - SIGD | C29: Consórcio BGPI | D29: =60*8*15 -> 7200 | E29: 238 | F29: =(D29/60)*E29 -> 28560 | G29: Diluido | H29: 12 | I29: =IF(OR(F29="",H29=""),"",IF(G29="À vista",F29,IFERROR(F29/H29,""))) -> 2380 | J29: =IF(F29="","",F29) -> 28560
A30: 28 | B30: BGPI - SISTEMA DE CAMPO | C30: Consórcio BGPI | D30: =60*8*7 -> 3360 | E30: 238 | F30: =(D30/60)*E30 -> 13328 | G30: Diluido | H30: 18 | I30: =IF(OR(F30="",H30=""),"",IF(G30="À vista",F30,IFERROR(F30/H30,""))) -> 740.44444 | J30: =IF(F30="","",F30) -> 13328
A31: 29 | B31: BONIN MANAGER | C31: Consórcio Habita REURBSP | D31: =60*8*15 -> 7200 | E31: 238 | F31: =(D31/60)*E31 -> 28560 | G31: Diluido | H31: 18 | I31: =IF(OR(F31="",H31=""),"",IF(G31="À vista",F31,IFERROR(F31/H31,""))) -> 1586.6667 | J31: =IF(F31="","",F31) -> 28560
A32: 30 | B32: BONIN - CHAMADOS DE TI | C32: Bonin Engenharia | D32: =60*8*10 -> 4800 | E32: 238 | F32: =(D32/60)*E32 -> 19040 | G32: Diluido | H32: 12 | I32: =IF(OR(F32="",H32=""),"",IF(G32="À vista",F32,IFERROR(F32/H32,""))) -> 1586.6667 | J32: =IF(F32="","",F32) -> 19040
A33: 31 | B33: BONIN - CONTROLE DE CONTRATOS | C33: Bonin Engenharia | D33: =60*8*40 -> 19200 | E33: 238 | F33: =(D33/60)*E33 -> 76160 | G33: Diluido | H33: 12 | I33: =IF(OR(F33="",H33=""),"",IF(G33="À vista",F33,IFERROR(F33/H33,""))) -> 6346.6667 | J33: =IF(F33="","",F33) -> 76160
A34: 32 | B34: BONIN - CONTROLE DE FROTAS | C34: Bonin Engenharia | D34: =60*8*20 -> 9600 | E34: 238 | F34: =(D34/60)*E34 -> 38080 | G34: Diluido | H34: 12 | I34: =IF(OR(F34="",H34=""),"",IF(G34="À vista",F34,IFERROR(F34/H34,""))) -> 3173.3333 | J34: =IF(F34="","",F34) -> 38080
A35: 33 | B35: BONIN - CONTROLE DE PROPOSTAS | C35: Bonin Engenharia | D35: =60*8*40 -> 19200 | E35: 238 | F35: =(D35/60)*E35 -> 76160 | G35: Diluido | H35: 12 | I35: =IF(OR(F35="",H35=""),"",IF(G35="À vista",F35,IFERROR(F35/H35,""))) -> 6346.6667 | J35: =IF(F35="","",F35) -> 76160
A36: 34 | B36: BONIN - CONTROLE DE RECIBOS | C36: Bonin Engenharia | D36: =60*8*3 -> 1440 | E36: 238 | F36: =(D36/60)*E36 -> 5712 | G36: Diluido | H36: 12 | I36: =IF(OR(F36="",H36=""),"",IF(G36="À vista",F36,IFERROR(F36/H36,""))) -> 476 | J36: =IF(F36="","",F36) -> 5712
A37: 35 | B37: BONIN - CULTURA SGI | C37: Bonin Engenharia | D37: =60*8*5 -> 2400 | E37: 238 | F37: =(D37/60)*E37 -> 9520 | G37: Diluido | H37: 12 | I37: =IF(OR(F37="",H37=""),"",IF(G37="À vista",F37,IFERROR(F37/H37,""))) -> 793.33333 | J37: =IF(F37="","",F37) -> 9520
A38: 36 | B38: BONIN - GESTÃO DE PESSOA JURÍDICA | C38: Bonin Engenharia | D38: =60*8*12 -> 5760 | E38: 238 | F38: =(D38/60)*E38 -> 22848 | G38: Diluido | H38: 12 | I38: =IF(OR(F38="",H38=""),"",IF(G38="À vista",F38,IFERROR(F38/H38,""))) -> 1904 | J38: =IF(F38="","",F38) -> 22848
A39: 37 | B39: BONIN - LANÇAMENTO DE KM'S | C39: Bonin Engenharia | D39: =60*8*4 -> 1920 | E39: 238 | F39: =(D39/60)*E39 -> 7616 | G39: Diluido | H39: 12 | I39: =IF(OR(F39="",H39=""),"",IF(G39="À vista",F39,IFERROR(F39/H39,""))) -> 634.66667 | J39: =IF(F39="","",F39) -> 7616
E40: 238 | F40: =(D40/60)*E40 -> 0 | G40: Diluido | H40: 12 | I40: =IF(OR(F40="",H40=""),"",IF(G40="À vista",F40,IFERROR(F40/H40,""))) -> 0 | J40: =IF(F40="","",F40) -> 0
...

Sheet Automacoes
A1: 🤖 AUTOMAÇÕES — Desenvolvimento e ROI por Consórcio
A2: Cada automação tem CAPEX próprio de desenvolvimento (à vista ou diluído), igual ao modelo de sistemas ERP.
A3: IDENTIFICAÇÃO | D3: 📌 PROCESSO MANUAL | H3: ⚙️ DESENVOLVIMENTO E COBRANÇA | M3: 📊 ROI
A4: # | B4: Automação | C4: Consórcio | D4: Tempo Manual (min/exec) | E4: Freq. Mensal | F4: Custo/h Respons. | G4: Tempo Autom. (min/exec) | H4: Horas Dev | I4: CAPEX Dev (R$) | J4: Forma Cobrança | K4: Prazo (meses) | L4: Parcela CAPEX/mês (R$) | M4: Economia 6m (R$) | N4: Economia 12m (R$)
A5: 1 | B5: Relatorio Dossie Habitação (Habita Sampa) | C5: Consórcio URBHIS | D5: 120 | E5: 20 | F5: 238 | G5: 5 | H5: 1800 | I5: =IF((H5/60)="","",(H5/60)*Config!$E$12) -> 7140 | J5: Diluido | K5: 12 | L5: =IF(OR(I5="",K5=""),"",IF(J5="A vista",I5,IFERROR(I5/K5,""))) -> 595 | M5: =IF(OR(D5="",E5=""),"",((D5-G5)/60*E5*F5)*6) -> 54740 | N5: =IF(OR(D5="",E5=""),"",((D5-G5)/60*E5*F5)*12) -> 109480
A6: 2 | B6: Relatorio Dossie Habitação (Validação de Dossie Cohab) | C6: Consórcio URBHIS | D6: 480 | E6: 20 | F6: 37.5 | G6: 10 | H6: 1800 | I6: =IF((H6/60)="","",(H6/60)*Config!$E$12) -> 7140 | J6: Diluido | K6: 12 | L6: =IF(OR(I6="",K6=""),"",IF(J6="A vista",I6,IFERROR(I6/K6,""))) -> 595 | M6: =IF(OR(D6="",E6=""),"",((D6-G6)/60*E6*F6)*6) -> 35250 | N6: =IF(OR(D6="",E6=""),"",((D6-G6)/60*E6*F6)*12) -> 70500
A7: 3 | B7: Relatório Planejamento Semanal | C7: Consórcio URBHIS | F7: 238 | G7: 1 | H7: 240 | I7: =IF((H7/60)="","",(H7/60)*Config!$E$12) -> 952 | J7: Diluido | K7: 12 | L7: =IF(OR(I7="",K7=""),"",IF(J7="A vista",I7,IFERROR(I7/K7,""))) -> 79.333333 | M7: =IF(OR(D7="",E7=""),"",((D7-G7)/60*E7*F7)*6) | N7: =IF(OR(D7="",E7=""),"",((D7-G7)/60*E7*F7)*12)
A8: 4 | B8: Relatório Atendimentos – Urbhis | C8: Consórcio URBHIS | F8: 238 | G8: 4 | H8: 1440 | I8: =IF((H8/60)="","",(H8/60)*Config!$E$12) -> 5712 | J8: Diluido | K8: 12 | L8: =IF(OR(I8="",K8=""),"",IF(J8="A vista",I8,IFERROR(I8/K8,""))) -> 476 | M8: =IF(OR(D8="",E8=""),"",((D8-G8)/60*E8*F8)*6) | N8: =IF(OR(D8="",E8=""),"",((D8-G8)/60*E8*F8)*12)
A9: 5 | B9: Relatório Agendamentos – Urbhis | C9: Consórcio URBHIS | F9: 238 | G9: 4 | H9: 720 | I9: =IF((H9/60)="","",(H9/60)*Config!$E$12) -> 2856 | J9: Diluido | K9: 12 | L9: =IF(OR(I9="",K9=""),"",IF(J9="A vista",I9,IFERROR(I9/K9,""))) -> 238 | M9: =IF(OR(D9="",E9=""),"",((D9-G9)/60*E9*F9)*6) | N9: =IF(OR(D9="",E9=""),"",((D9-G9)/60*E9*F9)*12)
A10: 6 | B10: Relatório Sintético P4 | C10: Consórcio URBHIS | F10: 238 | G10: 3 | H10: 960 | I10: =IF((H10/60)="","",(H10/60)*Config!$E$12) -> 3808 | J10: Diluido | K10: 12 | L10: =IF(OR(I10="",K10=""),"",IF(J10="A vista",I10,IFERROR(I10/K10,""))) -> 317.33333 | M10: =IF(OR(D10="",E10=""),"",((D10-G10)/60*E10*F10)*6) | N10: =IF(OR(D10="",E10=""),"",((D10-G10)/60*E10*F10)*12)
A11: 7 | B11: Relatório Fotográfico – Urbhis | C11: Consórcio URBHIS | F11: 238 | G11: 0.1 | H11: 960 | I11: =IF((H11/60)="","",(H11/60)*Config!$E$12) -> 3808 | J11: Diluido | K11: 12 | L11: =IF(OR(I11="",K11=""),"",IF(J11="A vista",I11,IFERROR(I11/K11,""))) -> 317.33333 | M11: =IF(OR(D11="",E11=""),"",((D11-G11)/60*E11*F11)*6) | N11: =IF(OR(D11="",E11=""),"",((D11-G11)/60*E11*F11)*12)
A12: 8 | B12: Relatório Zapito | C12: Consórcio URBHIS | D12: 60 | E12: 4 | F12: 37.5 | G12: 0.5 | H12: =60*8*2 -> 960 | I12: =IF((H12/60)="","",(H12/60)*Config!$E$12) -> 3808 | J12: Diluido | K12: 12 | L12: =IF(OR(I12="",K12=""),"",IF(J12="A vista",I12,IFERROR(I12/K12,""))) -> 317.33333 | M12: =IF(OR(D12="",E12=""),"",((D12-G12)/60*E12*F12)*6) -> 892.5 | N12: =IF(OR(D12="",E12=""),"",((D12-G12)/60*E12*F12)*12) -> 1785
A13: 9 | B13: Relatório Ordem de Serviço | C13: Consórcio URBHIS | D13: 1440 | E13: 1 | F13: =10000/20/8 -> 62.5 | G13: 3 | H13: =60*8*4 -> 1920 | I13: =IF((H13/60)="","",(H13/60)*Config!$E$12) -> 7616 | J13: Diluido | K13: 12 | L13: =IF(OR(I13="",K13=""),"",IF(J13="A vista",I13,IFERROR(I13/K13,""))) -> 634.66667 | M13: =IF(OR(D13="",E13=""),"",((D13-G13)/60*E13*F13)*6) -> 8981.25 | N13: =IF(OR(D13="",E13=""),"",((D13-G13)/60*E13*F13)*12) -> 17962.5
A14: 10 | B14: Power BI - ordem_de_servico_urbhis | C14: Consórcio URBHIS | F14: 238 | H14: =60*8*3 -> 1440 | I14: =IF((H14/60)="","",(H14/60)*Config!$E$12) -> 5712 | J14: Diluido | K14: 12 | L14: =IF(OR(I14="",K14=""),"",IF(J14="A vista",I14,IFERROR(I14/K14,""))) -> 476 | M14: =IF(OR(D14="",E14=""),"",((D14-G14)/60*E14*F14)*6) | N14: =IF(OR(D14="",E14=""),"",((D14-G14)/60*E14*F14)*12)
A15: 11 | B15: Power BI - Atendimentos | C15: Consórcio URBHIS | F15: 238 | H15: 180 | I15: =IF((H15/60)="","",(H15/60)*Config!$E$12) -> 714 | J15: Diluido | K15: 12 | L15: =IF(OR(I15="",K15=""),"",IF(J15="A vista",I15,IFERROR(I15/K15,""))) -> 59.5 | M15: =IF(OR(D15="",E15=""),"",((D15-G15)/60*E15*F15)*6) | N15: =IF(OR(D15="",E15=""),"",((D15-G15)/60*E15*F15)*12)
A16: 12 | B16: Power BI - Mapa de Conteudo | C16: Consórcio URBHIS | F16: 238 | H16: =60*8*2 -> 960 | I16: =IF((H16/60)="","",(H16/60)*Config!$E$12) -> 3808 | J16: Diluido | K16: 12 | L16: =IF(OR(I16="",K16=""),"",IF(J16="A vista",I16,IFERROR(I16/K16,""))) -> 317.33333 | M16: =IF(OR(D16="",E16=""),"",((D16-G16)/60*E16*F16)*6) | N16: =IF(OR(D16="",E16=""),"",((D16-G16)/60*E16*F16)*12)
A17: 13 | B17: Relatório de Notificações Vinci | C17: Vinci Notificações | D17: 480 | E17: 4 | F17: 37.5 | G17: 0.5 | H17: 720 | I17: =IF((H17/60)="","",(H17/60)*Config!$E$12) -> 2856 | J17: Diluido | K17: 12 | L17: =IF(OR(I17="",K17=""),"",IF(J17="A vista",I17,IFERROR(I17/K17,""))) -> 238 | M17: =IF(OR(D17="",E17=""),"",((D17-G17)/60*E17*F17)*6) -> 7192.5 | N17: =IF(OR(D17="",E17=""),"",((D17-G17)/60*E17*F17)*12) -> 14385
A18: 14 | B18: Relatório Geral Notificações Vinci | C18: Vinci Notificações | D18: 480 | E18: 4 | F18: 37.5 | G18: 0.5 | H18: =60*6 -> 360 | I18: =IF((H18/60)="","",(H18/60)*Config!$E$12) -> 1428 | J18: Diluido | K18: 12 | L18: =IF(OR(I18="",K18=""),"",IF(J18="A vista",I18,IFERROR(I18/K18,""))) -> 119 | M18: =IF(OR(D18="",E18=""),"",((D18-G18)/60*E18*F18)*6) -> 7192.5 | N18: =IF(OR(D18="",E18=""),"",((D18-G18)/60*E18*F18)*12) -> 14385
A19: 15 | B19: Power Bi - Cabiunas_AcompanhamentoSelos | C19: Macaé Petrobrás | F19: 238 | H19: =60*8*3 -> 1440 | I19: =IF((H19/60)="","",(H19/60)*Config!$E$12) -> 5712 | J19: Diluido | K19: 12 | L19: =IF(OR(I19="",K19=""),"",IF(J19="A vista",I19,IFERROR(I19/K19,""))) -> 476 | M19: =IF(OR(D19="",E19=""),"",((D19-G19)/60*E19*F19)*6) | N19: =IF(OR(D19="",E19=""),"",((D19-G19)/60*E19*F19)*12)
A20: 16 | B20: Relatório de Atendimentos – Cabiunas | C20: Macaé Petrobrás | D20: 20 | E20: 8 | F20: 37.5 | G20: 0.5 | H20: =60*6 -> 360 | I20: =IF((H20/60)="","",(H20/60)*Config!$E$12) -> 1428 | J20: Diluido | K20: 12 | L20: =IF(OR(I20="",K20=""),"",IF(J20="A vista",I20,IFERROR(I20/K20,""))) -> 119 | M20: =IF(OR(D20="",E20=""),"",((D20-G20)/60*E20*F20)*6) -> 585 | N20: =IF(OR(D20="",E20=""),"",((D20-G20)/60*E20*F20)*12) -> 1170
A21: 17 | B21: Relatório de Compensação – Cabiunas | C21: Macaé Petrobrás | D21: =60*2 -> 120 | E21: 12 | F21: 37.5 | G21: 5 | H21: =60*8*2 -> 960 | I21: =IF((H21/60)="","",(H21/60)*Config!$E$12) -> 3808 | J21: Diluido | K21: 12 | L21: =IF(OR(I21="",K21=""),"",IF(J21="A vista",I21,IFERROR(I21/K21,""))) -> 317.33333 | M21: =IF(OR(D21="",E21=""),"",((D21-G21)/60*E21*F21)*6) -> 5175 | N21: =IF(OR(D21="",E21=""),"",((D21-G21)/60*E21*F21)*12) -> 10350
A22: 18 | B22: Relatório Compensação Inquilinos | C22: Macaé Petrobrás | D22: =60*2 -> 120 | E22: 12 | F22: 37.5 | G22: 5 | H22: =60*8*4 -> 1920 | I22: =IF((H22/60)="","",(H22/60)*Config!$E$12) -> 7616 | J22: Diluido | K22: 12 | L22: =IF(OR(I22="",K22=""),"",IF(J22="A vista",I22,IFERROR(I22/K22,""))) -> 634.66667 | M22: =IF(OR(D22="",E22=""),"",((D22-G22)/60*E22*F22)*6) -> 5175 | N22: =IF(OR(D22="",E22=""),"",((D22-G22)/60*E22*F22)*12) -> 10350
A23: 19 | B23: Relatório de Atualização Cadastral Físico | C23: Macaé Petrobrás | D23: 60 | E23: 8 | F23: 37.5 | G23: 0.5 | H23: =60*6 -> 360 | I23: =IF((H23/60)="","",(H23/60)*Config!$E$12) -> 1428 | J23: Diluido | K23: 12 | L23: =IF(OR(I23="",K23=""),"",IF(J23="A vista",I23,IFERROR(I23/K23,""))) -> 119 | M23: =IF(OR(D23="",E23=""),"",((D23-G23)/60*E23*F23)*6) -> 1785 | N23: =IF(OR(D23="",E23=""),"",((D23-G23)/60*E23*F23)*12) -> 3570
A24: 20 | B24: Relatório de Atualização Cadastral Social | C24: Macaé Petrobrás | D24: 60 | E24: 8 | F24: 37.5 | G24: 0.5 | H24: =60*6 -> 360 | I24: =IF((H24/60)="","",(H24/60)*Config!$E$12) -> 1428 | J24: Diluido | K24: 12 | L24: =IF(OR(I24="",K24=""),"",IF(J24="A vista",I24,IFERROR(I24/K24,""))) -> 119 | M24: =IF(OR(D24="",E24=""),"",((D24-G24)/60*E24*F24)*6) -> 1785 | N24: =IF(OR(D24="",E24=""),"",((D24-G24)/60*E24*F24)*12) -> 3570
A25: 21 | B25: Relatório de Atualização Dados Bancários | C25: Macaé Petrobrás | D25: 60 | E25: 8 | F25: 37.5 | G25: 0.5 | H25: =60*6 -> 360 | I25: =IF((H25/60)="","",(H25/60)*Config!$E$12) -> 1428 | J25: Diluido | K25: 12 | L25: =IF(OR(I25="",K25=""),"",IF(J25="A vista",I25,IFERROR(I25/K25,""))) -> 119 | M25: =IF(OR(D25="",E25=""),"",((D25-G25)/60*E25*F25)*6) -> 1785 | N25: =IF(OR(D25="",E25=""),"",((D25-G25)/60*E25*F25)*12) -> 3570
A26: 22 | B26: Relatório Selo x Etapa | C26: Macaé Petrobrás | D26: 60 | E26: 8 | F26: 37.5 | G26: 0.5 | H26: =60*6 -> 360 | I26: =IF((H26/60)="","",(H26/60)*Config!$E$12) -> 1428 | J26: Diluido | K26: 12 | L26: =IF(OR(I26="",K26=""),"",IF(J26="A vista",I26,IFERROR(I26/K26,""))) -> 119 | M26: =IF(OR(D26="",E26=""),"",((D26-G26)/60*E26*F26)*6) -> 1785 | N26: =IF(OR(D26="",E26=""),"",((D26-G26)/60*E26*F26)*12) -> 3570
A27: 23 | B27: Relatório Extrator Selo | C27: Macaé Petrobrás | D27: 60 | E27: 8 | F27: 37.5 | G27: 0.5 | H27: =60*6 -> 360 | I27: =IF((H27/60)="","",(H27/60)*Config!$E$12) -> 1428 | J27: Diluido | K27: 12 | L27: =IF(OR(I27="",K27=""),"",IF(J27="A vista",I27,IFERROR(I27/K27,""))) -> 119 | M27: =IF(OR(D27="",E27=""),"",((D27-G27)/60*E27*F27)*6) -> 1785 | N27: =IF(OR(D27="",E27=""),"",((D27-G27)/60*E27*F27)*12) -> 3570
A28: 24 | B28: Relatório Extrator Social | C28: Macaé Petrobrás | D28: 60 | E28: 8 | F28: 37.5 | G28: 0.5 | H28: =60*6 -> 360 | I28: =IF((H28/60)="","",(H28/60)*Config!$E$12) -> 1428 | J28: Diluido | K28: 12 | L28: =IF(OR(I28="",K28=""),"",IF(J28="A vista",I28,IFERROR(I28/K28,""))) -> 119 | M28: =IF(OR(D28="",E28=""),"",((D28-G28)/60*E28*F28)*6) -> 1785 | N28: =IF(OR(D28="",E28=""),"",((D28-G28)/60*E28*F28)*12) -> 3570
A29: 25 | B29: Relatório de Negociação – Cabiunas | C29: Macaé Petrobrás | F29: 37.5 | I29: =IF((H29/60)="","",(H29/60)*Config!$E$12) -> 0 | J29: Diluido | K29: 12 | L29: =IF(OR(I29="",K29=""),"",IF(J29="A vista",I29,IFERROR(I29/K29,""))) -> 0 | M29: =IF(OR(D29="",E29=""),"",((D29-G29)/60*E29*F29)*6) | N29: =IF(OR(D29="",E29=""),"",((D29-G29)/60*E29*F29)*12)
A30: 26 | B30: Relatório de Acompanhamento Social | C30: Macaé Petrobrás | D30: 180 | E30: 4 | F30: 37.5 | G30: 1 | H30: =60*8*2 -> 960 | I30: =IF((H30/60)="","",(H30/60)*Config!$E$12) -> 3808 | J30: Diluido | K30: 12 | L30: =IF(OR(I30="",K30=""),"",IF(J30="A vista",I30,IFERROR(I30/K30,""))) -> 317.33333 | M30: =IF(OR(D30="",E30=""),"",((D30-G30)/60*E30*F30)*6) -> 2685 | N30: =IF(OR(D30="",E30=""),"",((D30-G30)/60*E30*F30)*12) -> 5370
A31: 27 | B31: Power BI - Habita Social Lançamento de Kms | C31: Consórcio HABITA SOCIAL | D31: =60*8*3 -> 1440 | F31: 238 | H31: =60*8*2 -> 960 | I31: =IF((H31/60)="","",(H31/60)*Config!$E$12) -> 3808 | J31: Diluido | K31: 12 | L31: =IF(OR(I31="",K31=""),"",IF(J31="A vista",I31,IFERROR(I31/K31,""))) -> 317.33333 | M31: =IF(OR(D31="",E31=""),"",((D31-G31)/60*E31*F31)*6) | N31: =IF(OR(D31="",E31=""),"",((D31-G31)/60*E31*F31)*12)
A32: 28 | B32: Power Automate - Fluxo De Alerta Ocorrência KM's | C32: Consórcio HABITA SOCIAL | F32: 238 | H32: =60*4 -> 240 | I32: =IF((H32/60)="","",(H32/60)*Config!$E$12) -> 952 | J32: Diluido | K32: 12 | L32: =IF(OR(I32="",K32=""),"",IF(J32="A vista",I32,IFERROR(I32/K32,""))) -> 79.333333 | M32: =IF(OR(D32="",E32=""),"",((D32-G32)/60*E32*F32)*6) | N32: =IF(OR(D32="",E32=""),"",((D32-G32)/60*E32*F32)*12)
A33: 29 | B33: Avanço selagem | C33: COHAB SANTOS | D33: 30 | E33: 1 | F33: =5000/20/8 -> 31.25 | G33: 1 | H33: 60 | I33: =IF((H33/60)="","",(H33/60)*Config!$E$12) -> 238 | J33: Diluido | K33: 12 | L33: =IF(OR(I33="",K33=""),"",IF(J33="A vista",I33,IFERROR(I33/K33,""))) -> 19.833333 | M33: =IF(OR(D33="",E33=""),"",((D33-G33)/60*E33*F33)*6) -> 90.625 | N33: =IF(OR(D33="",E33=""),"",((D33-G33)/60*E33*F33)*12) -> 181.25
A34: 30 | B34: Mapa avanço selagem | C34: COHAB SANTOS | D34: 30 | E34: 1 | F34: =5000/20/8 -> 31.25 | G34: 1 | H34: 60 | I34: =IF((H34/60)="","",(H34/60)*Config!$E$12) -> 238 | J34: Diluido | K34: 12 | L34: =IF(OR(I34="",K34=""),"",IF(J34="A vista",I34,IFERROR(I34/K34,""))) -> 19.833333 | M34: =IF(OR(D34="",E34=""),"",((D34-G34)/60*E34*F34)*6) -> 90.625 | N34: =IF(OR(D34="",E34=""),"",((D34-G34)/60*E34*F34)*12) -> 181.25
A35: 31 | B35: Selagem cadastro | C35: COHAB SANTOS | D35: =3*60 -> 180 | E35: 10 | F35: =5000/20/8 -> 31.25 | G35: 2 | H35: 60 | I35: =IF((H35/60)="","",(H35/60)*Config!$E$12) -> 238 | J35: Diluido | K35: 12 | L35: =IF(OR(I35="",K35=""),"",IF(J35="A vista",I35,IFERROR(I35/K35,""))) -> 19.833333 | M35: =IF(OR(D35="",E35=""),"",((D35-G35)/60*E35*F35)*6) -> 5562.5 | N35: =IF(OR(D35="",E35=""),"",((D35-G35)/60*E35*F35)*12) -> 11125
A36: 32 | B36: Relatório de Diário de Obra | C36: Consórcio BGGK | D36: 60 | E36: 20 | F36: =7000/20/8 -> 43.75 | G36: 0.5 | H36: =60*6 -> 360 | I36: =IF((H36/60)="","",(H36/60)*Config!$E$12) -> 1428 | J36: Diluido | K36: 12 | L36: =IF(OR(I36="",K36=""),"",IF(J36="A vista",I36,IFERROR(I36/K36,""))) -> 119 | M36: =IF(OR(D36="",E36=""),"",((D36-G36)/60*E36*F36)*6) -> 5206.25 | N36: =IF(OR(D36="",E36=""),"",((D36-G36)/60*E36*F36)*12) -> 10412.5
A37: 33 | B37: Relatório de Não Conformidade | C37: Consórcio BGGK | D37: =2*60 -> 120 | E37: 6 | F37: =7000/20/8 -> 43.75 | G37: 0.5 | H37: =60*2 -> 120 | I37: =IF((H37/60)="","",(H37/60)*Config!$E$12) -> 476 | J37: Diluido | K37: 12 | L37: =IF(OR(I37="",K37=""),"",IF(J37="A vista",I37,IFERROR(I37/K37,""))) -> 39.666667 | M37: =IF(OR(D37="",E37=""),"",((D37-G37)/60*E37*F37)*6) -> 3136.875 | N37: =IF(OR(D37="",E37=""),"",((D37-G37)/60*E37*F37)*12) -> 6273.75
A38: 34 | B38: Relatório Automatizado Medição | C38: Consórcio HABITA GERENCIAL | D38: =60*8*2 -> 960 | E38: 5 | F38: 238 | G38: 2 | H38: =8*60*8 -> 3840 | I38: =IF((H38/60)="","",(H38/60)*Config!$E$12) -> 15232 | J38: Diluido | K38: 12 | L38: =IF(OR(I38="",K38=""),"",IF(J38="A vista",I38,IFERROR(I38/K38,""))) -> 1269.3333 | M38: =IF(OR(D38="",E38=""),"",((D38-G38)/60*E38*F38)*6) -> 114002 | N38: =IF(OR(D38="",E38=""),"",((D38-G38)/60*E38*F38)*12) -> 228004
A39: 35 | B39: Power BI - acomp_contrato_bjmm | C39: Consórcio BJMM | F39: 238 | H39: 960 | I39: =IF((H39/60)="","",(H39/60)*Config!$E$12) -> 3808 | J39: Diluido | K39: 12 | L39: =IF(OR(I39="",K39=""),"",IF(J39="A vista",I39,IFERROR(I39/K39,""))) -> 317.33333 | M39: =IF(OR(D39="",E39=""),"",((D39-G39)/60*E39*F39)*6) | N39: =IF(OR(D39="",E39=""),"",((D39-G39)/60*E39*F39)*12)
A40: 36 | B40: Power BI - BJMM_Fiscalizacao | C40: Consórcio BJMM | F40: 238 | H40: 1440 | I40: =IF((H40/60)="","",(H40/60)*Config!$E$12) -> 5712 | J40: Diluido | K40: 12 | L40: =IF(OR(I40="",K40=""),"",IF(J40="A vista",I40,IFERROR(I40/K40,""))) -> 476 | M40: =IF(OR(D40="",E40=""),"",((D40-G40)/60*E40*F40)*6) | N40: =IF(OR(D40="",E40=""),"",((D40-G40)/60*E40*F40)*12)
...

Sheet Extrato Consorcios
A1: 📋 EXTRATO DE COBRANÇA — Resumo por Consórcio
A2: Visão consolidada por consórcio: porte, mensalidade, CAPEX sistemas, CAPEX automações e ROI total.
A3: IDENTIFICAÇÃO E PORTE | E3: 💳 MENSALIDADE | G3: 🖥️ CAPEX SISTEMAS | I3: 🤖 CAPEX AUTOMAÇÕES | K3: 💰 TOTAL MENSAL | L3: 📊 ATIVOS | N3: 📈 ROI
A4: # | B4: Consórcio | C4: Índice Porte | D4: Classificação | E4: Mensalidade Base (R$) | F4: Horas/mês Destinadas | G4: CAPEX Total Sistemas (R$) | H4: Parcela Sist. /mês (R$) | I4: CAPEX Total Autom. (R$) | J4: Parcela Autom. /mês (R$) | K4: Total Mensal (R$) | L4: Nº Sist. | M4: Nº Autom. | N4: Eco. Anual Autom. (R$)
A5: 1 | B5: Consórcio BGGK | C5: =IFERROR(VLOOKUP(B5,Consorcios!$B$5:$L$24,9,0),"") -> 0.25 | D5: =IF(C5="","",IF(C5<0.25,"Micro",IF(C5<0.5,"Pequeno",IF(C5<0.75,"Medio","Grande")))) -> Pequeno | E5: =IFERROR(VLOOKUP(B5,Consorcios!$B$5:$L$24,11,0),"") -> 1904 | F5: 8 | G5: =SUMIF('Sistemas ERP'!$C$5:$C$56,B5,'Sistemas ERP'!$F$5:$F$56) -> 24752 | H5: =SUMIF('Sistemas ERP'!$C$5:$C$56,B5,'Sistemas ERP'!$I$5:$I$56) -> 2062.6667 | I5: =SUMIF(Automacoes!$C$5:$C$99,B5,Automacoes!$I$5:$I$99) -> 1904 | J5: =SUMIF(Automacoes!$C$5:$C$99,B5,Automacoes!$L$5:$L$99) -> 158.66667 | K5: =IF(E5="","",E5+H5+J5) -> 4125.3333 | L5: =COUNTIF('Sistemas ERP'!$C$5:$C$56,B5) -> 2 | M5: =COUNTIF(Automacoes!$C$5:$C$99,B5) -> 3 | N5: =SUMIF(Automacoes!$C$5:$C$99,B5,Automacoes!$N$5:$N$99) -> 16686.25
A6: 2 | B6: COHAB SANTOS | C6: =IFERROR(VLOOKUP(B6,Consorcios!$B$5:$L$24,9,0),"") -> 0.15 | D6: =IF(C6="","",IF(C6<0.25,"Micro",IF(C6<0.5,"Pequeno",IF(C6<0.75,"Medio","Grande")))) -> Micro | E6: =IFERROR(VLOOKUP(B6,Consorcios!$B$5:$L$24,11,0),"") -> 952 | F6: =IFERROR(VLOOKUP(B6,Consorcios!$B$5:$L$24,10,0),"") -> 4 | G6: =SUMIF('Sistemas ERP'!$C$5:$C$56,B6,'Sistemas ERP'!$F$5:$F$56) -> 39984 | H6: =SUMIF('Sistemas ERP'!$C$5:$C$56,B6,'Sistemas ERP'!$I$5:$I$56) -> 3332 | I6: =SUMIF(Automacoes!$C$5:$C$99,B6,Automacoes!$I$5:$I$99) -> 714 | J6: =SUMIF(Automacoes!$C$5:$C$99,B6,Automacoes!$L$5:$L$99) -> 59.5 | K6: =IF(E6="","",E6+H6+J6) -> 4343.5 | L6: =COUNTIF('Sistemas ERP'!$C$5:$C$56,B6) -> 2 | M6: =COUNTIF(Automacoes!$C$5:$C$99,B6) -> 3 | N6: =SUMIF(Automacoes!$C$5:$C$99,B6,Automacoes!$N$5:$N$99) -> 11487.5
A7: 3 | B7: Consórcio BJMM | C7: =IFERROR(VLOOKUP(B7,Consorcios!$B$5:$L$24,9,0),"") -> 0.675 | D7: =IF(C7="","",IF(C7<0.25,"Micro",IF(C7<0.5,"Pequeno",IF(C7<0.75,"Medio","Grande")))) -> Medio | E7: =IFERROR(VLOOKUP(B7,Consorcios!$B$5:$L$24,11,0),"") -> 2856 | F7: =IFERROR(VLOOKUP(B7,Consorcios!$B$5:$L$24,10,0),"") -> 12 | G7: =SUMIF('Sistemas ERP'!$C$5:$C$56,B7,'Sistemas ERP'!$F$5:$F$56) -> 79968 | H7: =SUMIF('Sistemas ERP'!$C$5:$C$56,B7,'Sistemas ERP'!$I$5:$I$56) -> 6664 | I7: =SUMIF(Automacoes!$C$5:$C$99,B7,Automacoes!$I$5:$I$99) -> 26656 | J7: =SUMIF(Automacoes!$C$5:$C$99,B7,Automacoes!$L$5:$L$99) -> 2221.3333 | K7: =IF(E7="","",E7+H7+J7) -> 11741.333 | L7: =COUNTIF('Sistemas ERP'!$C$5:$C$56,B7) -> 3 | M7: =COUNTIF(Automacoes!$C$5:$C$99,B7) -> 15 | N7: =SUMIF(Automacoes!$C$5:$C$99,B7,Automacoes!$N$5:$N$99) -> 459482.8
A8: 4 | B8: ELETROBRAS | C8: =IFERROR(VLOOKUP(B8,Consorcios!$B$5:$L$24,9,0),"") -> 0.15 | D8: =IF(C8="","",IF(C8<0.25,"Micro",IF(C8<0.5,"Pequeno",IF(C8<0.75,"Medio","Grande")))) -> Micro | E8: =IFERROR(VLOOKUP(B8,Consorcios!$B$5:$L$24,11,0),"") -> 238 | F8: =IFERROR(VLOOKUP(B8,Consorcios!$B$5:$L$24,10,0),"") -> 1 | G8: =SUMIF('Sistemas ERP'!$C$5:$C$56,B8,'Sistemas ERP'!$F$5:$F$56) -> 38080 | H8: =SUMIF('Sistemas ERP'!$C$5:$C$56,B8,'Sistemas ERP'!$I$5:$I$56) -> 3173.3333 | I8: =SUMIF(Automacoes!$C$5:$C$99,B8,Automacoes!$I$5:$I$99) -> 0 | J8: =SUMIF(Automacoes!$C$5:$C$99,B8,Automacoes!$L$5:$L$99) -> 0 | K8: =IF(E8="","",E8+H8+J8) -> 3411.3333 | L8: =COUNTIF('Sistemas ERP'!$C$5:$C$56,B8) -> 1 | M8: =COUNTIF(Automacoes!$C$5:$C$99,B8) -> 0 | N8: =SUMIF(Automacoes!$C$5:$C$99,B8,Automacoes!$N$5:$N$99) -> 0
A9: 5 | B9: Consórcio HABITA GERENCIAL | C9: =IFERROR(VLOOKUP(B9,Consorcios!$B$5:$L$24,9,0),"") -> 0.675 | D9: =IF(C9="","",IF(C9<0.25,"Micro",IF(C9<0.5,"Pequeno",IF(C9<0.75,"Medio","Grande")))) -> Medio | E9: =IFERROR(VLOOKUP(B9,Consorcios!$B$5:$L$24,11,0),"") -> 3808 | F9: =IFERROR(VLOOKUP(B9,Consorcios!$B$5:$L$24,10,0),"") -> 16 | G9: =SUMIF('Sistemas ERP'!$C$5:$C$56,B9,'Sistemas ERP'!$F$5:$F$56) -> 49504 | H9: =SUMIF('Sistemas ERP'!$C$5:$C$56,B9,'Sistemas ERP'!$I$5:$I$56) -> 4125.3333 | I9: =SUMIF(Automacoes!$C$5:$C$99,B9,Automacoes!$I$5:$I$99) -> 95200 | J9: =SUMIF(Automacoes!$C$5:$C$99,B9,Automacoes!$L$5:$L$99) -> 7933.3333 | K9: =IF(E9="","",E9+H9+J9) -> 15866.667 | L9: =COUNTIF('Sistemas ERP'!$C$5:$C$56,B9) -> 3 | M9: =COUNTIF(Automacoes!$C$5:$C$99,B9) -> 4 | N9: =SUMIF(Automacoes!$C$5:$C$99,B9,Automacoes!$N$5:$N$99) -> 228004
A10: 6 | B10: Consórcio HABITA SOCIAL | C10: =IFERROR(VLOOKUP(B10,Consorcios!$B$5:$L$24,9,0),"") -> 1 | D10: =IF(C10="","",IF(C10<0.25,"Micro",IF(C10<0.5,"Pequeno",IF(C10<0.75,"Medio","Grande")))) -> Grande | E10: =IFERROR(VLOOKUP(B10,Consorcios!$B$5:$L$24,11,0),"") -> 952 | F10: =IFERROR(VLOOKUP(B10,Consorcios!$B$5:$L$24,10,0),"") -> 4 | G10: =SUMIF('Sistemas ERP'!$C$5:$C$56,B10,'Sistemas ERP'!$F$5:$F$56) -> 24520 | H10: =SUMIF('Sistemas ERP'!$C$5:$C$56,B10,'Sistemas ERP'!$I$5:$I$56) -> 2043.3333 | I10: =SUMIF(Automacoes!$C$5:$C$99,B10,Automacoes!$I$5:$I$99) -> 10472 | J10: =SUMIF(Automacoes!$C$5:$C$99,B10,Automacoes!$L$5:$L$99) -> 872.66667 | K10: =IF(E10="","",E10+H10+J10) -> 3868 | L10: =COUNTIF('Sistemas ERP'!$C$5:$C$56,B10) -> 3 | M10: =COUNTIF(Automacoes!$C$5:$C$99,B10) -> 3 | N10: =SUMIF(Automacoes!$C$5:$C$99,B10,Automacoes!$N$5:$N$99) -> 16593.75
A11: 7 | B11: Macaé Petrobrás | C11: =IFERROR(VLOOKUP(B11,Consorcios!$B$5:$L$24,9,0),"") -> 0.5 | D11: =IF(C11="","",IF(C11<0.25,"Micro",IF(C11<0.5,"Pequeno",IF(C11<0.75,"Medio","Grande")))) -> Medio | E11: =IFERROR(VLOOKUP(B11,Consorcios!$B$5:$L$24,11,0),"") -> 4760 | F11: =IFERROR(VLOOKUP(B11,Consorcios!$B$5:$L$24,10,0),"") -> 20 | G11: =SUMIF('Sistemas ERP'!$C$5:$C$56,B11,'Sistemas ERP'!$F$5:$F$56) -> 38080 | H11: =SUMIF('Sistemas ERP'!$C$5:$C$56,B11,'Sistemas ERP'!$I$5:$I$56) -> 3173.3333 | I11: =SUMIF(Automacoes!$C$5:$C$99,B11,Automacoes!$I$5:$I$99) -> 30940 | J11: =SUMIF(Automacoes!$C$5:$C$99,B11,Automacoes!$L$5:$L$99) -> 2578.3333 | K11: =IF(E11="","",E11+H11+J11) -> 10511.667 | L11: =COUNTIF('Sistemas ERP'!$C$5:$C$56,B11) -> 1 | M11: =COUNTIF(Automacoes!$C$5:$C$99,B11) -> 12 | N11: =SUMIF(Automacoes!$C$5:$C$99,B11,Automacoes!$N$5:$N$99) -> 48660
A12: 8 | B12: Consórcio REURBSP | C12: =IFERROR(VLOOKUP(B12,Consorcios!$B$5:$L$24,9,0),"") -> 1 | D12: =IF(C12="","",IF(C12<0.25,"Micro",IF(C12<0.5,"Pequeno",IF(C12<0.75,"Medio","Grande")))) -> Grande | E12: =IFERROR(VLOOKUP(B12,Consorcios!$B$5:$L$24,11,0),"") -> 7616 | F12: =IFERROR(VLOOKUP(B12,Consorcios!$B$5:$L$24,10,0),"") -> 32 | G12: =SUMIF('Sistemas ERP'!$C$5:$C$56,B12,'Sistemas ERP'!$F$5:$F$56) -> 0 | H12: =SUMIF('Sistemas ERP'!$C$5:$C$56,B12,'Sistemas ERP'!$I$5:$I$56) -> 0 | I12: =SUMIF(Automacoes!$C$5:$C$99,B12,Automacoes!$I$5:$I$99) -> 0 | J12: =SUMIF(Automacoes!$C$5:$C$99,B12,Automacoes!$L$5:$L$99) -> 0 | K12: =IF(E12="","",E12+H12+J12) -> 7616 | L12: =COUNTIF('Sistemas ERP'!$C$5:$C$56,B12) -> 0 | M12: =COUNTIF(Automacoes!$C$5:$C$99,B12) -> 4 | N12: =SUMIF(Automacoes!$C$5:$C$99,B12,Automacoes!$N$5:$N$99) -> 0
A13: 9 | B13: Consórcio URBHIS | C13: =IFERROR(VLOOKUP(B13,Consorcios!$B$5:$L$24,9,0),"") -> 1 | D13: =IF(C13="","",IF(C13<0.25,"Micro",IF(C13<0.5,"Pequeno",IF(C13<0.75,"Medio","Grande")))) -> Grande | E13: =IFERROR(VLOOKUP(B13,Consorcios!$B$5:$L$24,11,0),"") -> 9520 | F13: =IFERROR(VLOOKUP(B13,Consorcios!$B$5:$L$24,10,0),"") -> 40 | G13: =SUMIF('Sistemas ERP'!$C$5:$C$56,B13,'Sistemas ERP'!$F$5:$F$56) -> 76160 | H13: =SUMIF('Sistemas ERP'!$C$5:$C$56,B13,'Sistemas ERP'!$I$5:$I$56) -> 3173.3333 | I13: =SUMIF(Automacoes!$C$5:$C$99,B13,Automacoes!$I$5:$I$99) -> 53074 | J13: =SUMIF(Automacoes!$C$5:$C$99,B13,Automacoes!$L$5:$L$99) -> 4422.8333 | K13: =IF(E13="","",E13+H13+J13) -> 17116.167 | L13: =COUNTIF('Sistemas ERP'!$C$5:$C$56,B13) -> 4 | M13: =COUNTIF(Automacoes!$C$5:$C$99,B13) -> 12 | N13: =SUMIF(Automacoes!$C$5:$C$99,B13,Automacoes!$N$5:$N$99) -> 199727.5
A14: 10 | B14: Vinci Notificações | C14: =IFERROR(VLOOKUP(B14,Consorcios!$B$5:$L$24,9,0),"") -> 0.15 | D14: =IF(C14="","",IF(C14<0.25,"Micro",IF(C14<0.5,"Pequeno",IF(C14<0.75,"Medio","Grande")))) -> Micro | E14: =IFERROR(VLOOKUP(B14,Consorcios!$B$5:$L$24,11,0),"") -> 1190 | F14: =IFERROR(VLOOKUP(B14,Consorcios!$B$5:$L$24,10,0),"") -> 5 | G14: =SUMIF('Sistemas ERP'!$C$5:$C$56,B14,'Sistemas ERP'!$F$5:$F$56) -> 30464 | H14: =SUMIF('Sistemas ERP'!$C$5:$C$56,B14,'Sistemas ERP'!$I$5:$I$56) -> 2538.6667 | I14: =SUMIF(Automacoes!$C$5:$C$99,B14,Automacoes!$I$5:$I$99) -> 4284 | J14: =SUMIF(Automacoes!$C$5:$C$99,B14,Automacoes!$L$5:$L$99) -> 357 | K14: =IF(E14="","",E14+H14+J14) -> 4085.6667 | L14: =COUNTIF('Sistemas ERP'!$C$5:$C$56,B14) -> 2 | M14: =COUNTIF(Automacoes!$C$5:$C$99,B14) -> 2 | N14: =SUMIF(Automacoes!$C$5:$C$99,B14,Automacoes!$N$5:$N$99) -> 28770
A15: 11 | B15: COSAN | C15: =IFERROR(VLOOKUP(B15,Consorcios!$B$5:$L$24,9,0),"") -> 0.15 | D15: =IF(C15="","",IF(C15<0.25,"Micro",IF(C15<0.5,"Pequeno",IF(C15<0.75,"Medio","Grande")))) -> Micro | E15: =IFERROR(VLOOKUP(B15,Consorcios!$B$5:$L$24,11,0),"") -> 952 | F15: =IFERROR(VLOOKUP(B15,Consorcios!$B$5:$L$24,10,0),"") -> 4 | G15: =SUMIF('Sistemas ERP'!$C$5:$C$56,B15,'Sistemas ERP'!$F$5:$F$56) -> 51408 | H15: =SUMIF('Sistemas ERP'!$C$5:$C$56,B15,'Sistemas ERP'!$I$5:$I$56) -> 4284 | I15: =SUMIF(Automacoes!$C$5:$C$99,B15,Automacoes!$I$5:$I$99) -> 0 | J15: =SUMIF(Automacoes!$C$5:$C$99,B15,Automacoes!$L$5:$L$99) -> 0 | K15: =IF(E15="","",E15+H15+J15) -> 5236 | L15: =COUNTIF('Sistemas ERP'!$C$5:$C$56,B15) -> 3 | M15: =COUNTIF(Automacoes!$C$5:$C$99,B15) -> 2 | N15: =SUMIF(Automacoes!$C$5:$C$99,B15,Automacoes!$N$5:$N$99) -> 0
A16: 12 | B16: Consórcio BGPI | C16: =IFERROR(VLOOKUP(B16,Consorcios!$B$5:$L$24,9,0),"") -> 0.5 | D16: =IF(C16="","",IF(C16<0.25,"Micro",IF(C16<0.5,"Pequeno",IF(C16<0.75,"Medio","Grande")))) -> Medio | E16: =IFERROR(VLOOKUP(B16,Consorcios!$B$5:$L$24,11,0),"") -> 2856 | F16: =IFERROR(VLOOKUP(B16,Consorcios!$B$5:$L$24,10,0),"") -> 12 | G16: =SUMIF('Sistemas ERP'!$C$5:$C$56,B16,'Sistemas ERP'!$F$5:$F$56) -> 41888 | H16: =SUMIF('Sistemas ERP'!$C$5:$C$56,B16,'Sistemas ERP'!$I$5:$I$56) -> 3120.4444 | I16: =SUMIF(Automacoes!$C$5:$C$99,B16,Automacoes!$I$5:$I$99) -> 1904 | J16: =SUMIF(Automacoes!$C$5:$C$99,B16,Automacoes!$L$5:$L$99) -> 158.66667 | K16: =IF(E16="","",E16+H16+J16) -> 6135.1111 | L16: =COUNTIF('Sistemas ERP'!$C$5:$C$56,B16) -> 2 | M16: =COUNTIF(Automacoes!$C$5:$C$99,B16) -> 2 | N16: =SUMIF(Automacoes!$C$5:$C$99,B16,Automacoes!$N$5:$N$99) -> 16686.25
A17: 13 | B17: Consórcio Habita REURBSP | C17: =IFERROR(VLOOKUP(B17,Consorcios!$B$5:$L$24,9,0),"") -> 1 | D17: =IF(C17="","",IF(C17<0.25,"Micro",IF(C17<0.5,"Pequeno",IF(C17<0.75,"Medio","Grande")))) -> Grande | E17: =IFERROR(VLOOKUP(B17,Consorcios!$B$5:$L$24,11,0),"") -> 7616 | F17: =IFERROR(VLOOKUP(B17,Consorcios!$B$5:$L$24,10,0),"") -> 32 | G17: =SUMIF('Sistemas ERP'!$C$5:$C$56,B17,'Sistemas ERP'!$F$5:$F$56) -> 28560 | H17: =SUMIF('Sistemas ERP'!$C$5:$C$56,B17,'Sistemas ERP'!$I$5:$I$56) -> 1586.6667 | I17: =SUMIF(Automacoes!$C$5:$C$99,B17,Automacoes!$I$5:$I$99) -> 0 | J17: =SUMIF(Automacoes!$C$5:$C$99,B17,Automacoes!$L$5:$L$99) -> 0 | K17: =IF(E17="","",E17+H17+J17) -> 9202.6667 | L17: =COUNTIF('Sistemas ERP'!$C$5:$C$56,B17) -> 1 | M17: =COUNTIF(Automacoes!$C$5:$C$99,B17) -> 0 | N17: =SUMIF(Automacoes!$C$5:$C$99,B17,Automacoes!$N$5:$N$99) -> 0
